2024-03-04 19:08:22,094 INFO    StreamThr :15172 [internal.py:wandb_internal():86] W&B internal server running at pid: 15172, started at: 2024-03-04 19:08:22.091344
2024-03-04 19:08:22,102 DEBUG   HandlerThread:15172 [handler.py:handle_request():146] handle_request: status
2024-03-04 19:08:22,107 INFO    WriterThread:15172 [datastore.py:open_for_write():87] open: c:\Users\20998\Desktop\801Robot_code\fork_roboagent\wandb\run-20240304_190822-jyb7t62l\run-jyb7t62l.wandb
2024-03-04 19:08:22,114 DEBUG   SenderThread:15172 [sender.py:send():382] send: header
2024-03-04 19:08:22,208 DEBUG   SenderThread:15172 [sender.py:send():382] send: run
2024-03-04 19:08:26,581 INFO    SenderThread:15172 [retry.py:__call__():172] Retry attempt failed:
urllib3.exceptions.SSLError: TLS/SSL connection has been closed (EOF) (_ssl.c:1131)

The above exception was the direct cause of the following exception:

urllib3.exceptions.ProxyError: ('Unable to connect to proxy', SSLError(SSLZeroReturnError(6, 'TLS/SSL connection has been closed (EOF) (_ssl.c:1131)')))

The above exception was the direct cause of the following exception:

Traceback (most recent call last):
  File "c:\Users\20998\anaconda3\envs\act\lib\site-packages\requests\adapters.py", line 486, in send
    resp = conn.urlopen(
  File "c:\Users\20998\anaconda3\envs\act\lib\site-packages\urllib3\connectionpool.py", line 847, in urlopen
    retries = retries.increment(
  File "c:\Users\20998\anaconda3\envs\act\lib\site-packages\urllib3\util\retry.py", line 515, in increment
    raise MaxRetryError(_pool, url, reason) from reason  # type: ignore[arg-type]
urllib3.exceptions.MaxRetryError: HTTPSConnectionPool(host='api.wandb.ai', port=443): Max retries exceeded with url: /graphql (Caused by ProxyError('Unable to connect to proxy', SSLError(SSLZeroReturnError(6, 'TLS/SSL connection has been closed (EOF) (_ssl.c:1131)'))))

During handling of the above exception, another exception occurred:

Traceback (most recent call last):
  File "c:\Users\20998\anaconda3\envs\act\lib\site-packages\wandb\sdk\lib\retry.py", line 131, in __call__
    result = self._call_fn(*args, **kwargs)
  File "c:\Users\20998\anaconda3\envs\act\lib\site-packages\wandb\sdk\internal\internal_api.py", line 369, in execute
    return self.client.execute(*args, **kwargs)  # type: ignore
  File "c:\Users\20998\anaconda3\envs\act\lib\site-packages\wandb\vendor\gql-0.2.0\wandb_gql\client.py", line 52, in execute
    result = self._get_result(document, *args, **kwargs)
  File "c:\Users\20998\anaconda3\envs\act\lib\site-packages\wandb\vendor\gql-0.2.0\wandb_gql\client.py", line 60, in _get_result
    return self.transport.execute(document, *args, **kwargs)
  File "c:\Users\20998\anaconda3\envs\act\lib\site-packages\wandb\sdk\lib\gql_request.py", line 58, in execute
    request = self.session.post(self.url, **post_args)
  File "c:\Users\20998\anaconda3\envs\act\lib\site-packages\requests\sessions.py", line 637, in post
    return self.request("POST", url, data=data, json=json, **kwargs)
  File "c:\Users\20998\anaconda3\envs\act\lib\site-packages\requests\sessions.py", line 589, in request
    resp = self.send(prep, **send_kwargs)
  File "c:\Users\20998\anaconda3\envs\act\lib\site-packages\requests\sessions.py", line 703, in send
    r = adapter.send(request, **kwargs)
  File "c:\Users\20998\anaconda3\envs\act\lib\site-packages\requests\adapters.py", line 513, in send
    raise ProxyError(e, request=request)
requests.exceptions.ProxyError: HTTPSConnectionPool(host='api.wandb.ai', port=443): Max retries exceeded with url: /graphql (Caused by ProxyError('Unable to connect to proxy', SSLError(SSLZeroReturnError(6, 'TLS/SSL connection has been closed (EOF) (_ssl.c:1131)'))))
2024-03-04 19:08:27,261 DEBUG   HandlerThread:15172 [handler.py:handle_request():146] handle_request: keepalive
2024-03-04 19:08:32,303 DEBUG   HandlerThread:15172 [handler.py:handle_request():146] handle_request: keepalive
2024-03-04 19:08:37,360 DEBUG   HandlerThread:15172 [handler.py:handle_request():146] handle_request: keepalive
2024-03-04 19:08:42,414 DEBUG   HandlerThread:15172 [handler.py:handle_request():146] handle_request: keepalive
2024-03-04 19:08:47,444 DEBUG   HandlerThread:15172 [handler.py:handle_request():146] handle_request: keepalive
2024-03-04 19:08:52,500 DEBUG   HandlerThread:15172 [handler.py:handle_request():146] handle_request: keepalive
2024-03-04 19:08:57,521 DEBUG   HandlerThread:15172 [handler.py:handle_request():146] handle_request: keepalive
2024-03-04 19:09:10,999 DEBUG   HandlerThread:15172 [handler.py:handle_request():146] handle_request: shutdown
2024-03-04 19:09:10,999 INFO    HandlerThread:15172 [handler.py:finish():869] shutting down handler
2024-03-04 19:09:11,306 INFO    SenderThread:15172 [dir_watcher.py:__init__():211] watching files in: c:\Users\20998\Desktop\801Robot_code\fork_roboagent\wandb\run-20240304_190822-jyb7t62l\files
2024-03-04 19:09:11,306 INFO    SenderThread:15172 [sender.py:_start_run_threads():1136] run started: jyb7t62l with start time 1709550502.093341
2024-03-04 19:09:11,306 INFO    SenderThread:15172 [sender.py:finish():1572] shutting down sender
2024-03-04 19:09:11,307 INFO    SenderThread:15172 [dir_watcher.py:finish():358] shutting down directory watcher
2024-03-04 19:09:11,599 INFO    WriterThread:15172 [datastore.py:close():296] close: c:\Users\20998\Desktop\801Robot_code\fork_roboagent\wandb\run-20240304_190822-jyb7t62l\run-jyb7t62l.wandb
2024-03-04 19:09:12,314 INFO    SenderThread:15172 [dir_watcher.py:finish():388] scan: c:\Users\20998\Desktop\801Robot_code\fork_roboagent\wandb\run-20240304_190822-jyb7t62l\files
2024-03-04 19:09:12,316 INFO    SenderThread:15172 [dir_watcher.py:finish():402] scan save: c:\Users\20998\Desktop\801Robot_code\fork_roboagent\wandb\run-20240304_190822-jyb7t62l\files\config.yaml config.yaml
2024-03-04 19:09:12,317 INFO    SenderThread:15172 [file_pusher.py:finish():172] shutting down file pusher
2024-03-04 19:09:12,318 INFO    SenderThread:15172 [file_pusher.py:join():178] waiting for file pusher
